Workbook
Name ALM_COD: Configuraciones!$B$197:$B$237
Name ALM_NOM: Configuraciones!$C$197:$C$237
Name ALM_SEDE: Configuraciones!$D$197:$D$237
Name CAT_CV: OFFSET(Configuraciones!$D$10,0,0,MAX(COUNTA(Configuraciones!$D$10:$D$56),1),1)
Name CAT_NOMBRE: OFFSET(Configuraciones!$C$10,0,0,MAX(COUNTA(Configuraciones!$C$10:$C$56),1),1)
Name GRUPO_NOMBRE: Configuraciones!$C$6
Name LST_CODIGOS: OFFSET(Artículos!$A$2,0,0,MAX(COUNTIF(Artículos!$A$2:$A$213,"?*"),1),1)
Name PREFIJO: Configuraciones!$D$6
Name VACIO: Configuraciones!$A$2

Sheet 00 Guía
B1: GUÍA — PLANTILLA DE ARTÍCULOS · GRUPO: MATERIA PRIMA
C3: LEYENDA DE COLORES
C4: Columna OBLIGATORIA (*) — debe llenarse siempre
C5: Columna OPCIONAL — llénala solo si aplica
C6: Columna AUTOMÁTICA — no la edites: se calcula sola
C7: Fila de EJEMPLO — sobrescríbela o bórrala
C9: CÓMO LLENAR (hoja Artículos)
C10: • Una fila por artículo desde la fila 2 (la fila 2 es un ejemplo). No dejes filas vacías intermedias.
C11: • El CÓDIGO se genera SOLO cuando los 5 obligatorios están completos: Nombre, UM de Inventario, Control, IGV y Estado. Mientras falte alguno, la celda queda vacía.
C12: • Elige primero la Categoría; la Sub categoría muestra solo las de esa categoría (si no tiene, en blanco). La Valorización se completa sola.
C14: SUB-HOJAS (Atributos · Stock Mínimo · Códigos de Barras)
C15: • El «Código artículo» es un desplegable que SOLO muestra los códigos ya generados en la hoja Artículos; el nombre del artículo aparece solo.
C16: • En Stock Mínimo, al elegir el código de almacén aparecen su nombre y sede; la unidad se toma del artículo.
... C22: • Almacenes (bloque 12): lista de referencia con su sede, usada por Stock Mínimo.

Sheet Artículos
A1: Código (auto) | B1: Grupo de Artículo (auto) | C1: Categoría | D1: Sub categoría | E1: Nombre (*) | F1: Descripción | G1: UM de Inventario (*) | H1: Control de inventario (*) | I1: Valorización (auto) | J1: Apto para producción | K1: Precio venta sugerido S/. | L1: UM de venta | M1: Precio venta mínimo S/. | N1: Proveedor por defecto | O1: Precio compra ref. S/. | P1: UM de compra | Q1: Afectación IGV (*) | R1: Estado (*)
A2: =IF(OR($E2="",$G2="",$H2="",$Q2="",$R2=""),"",PREFIJO&TEXT(SUMPRODUCT(($E$2:$E2<>"")*($G$2:$G2<>"")*($H$2:$H2<>"")*($Q$2:$Q2<>"")*($R$2:$R2<>"")),"0000")) -> MP-0001 | B2: =IF($A2="","",GRUPO_NOMBRE) -> MATERIA PRIMA | C2: AVIOS DE ACABADOS PRINCIPALES | D2: CIERRES | E2: CIERRE METALICO 12CM BRONCE | F2: Cierre metálico bronce 12 cm | G2: UND | H2: Nada | I2: =IF($C2="","",IFERROR(INDEX(CAT_CV,MATCH($C2,CAT_NOMBRE,0)),"")) -> CV-02 | J2: No | N2: AVIOS DEL SUR EIRL | O2: 0.8 | P2: UND | Q2: Gravado - Operación Onerosa (18%) | R2: Activo
A3: =IF(OR($E3="",$G3="",$H3="",$Q3="",$R3=""),"",PREFIJO&TEXT(SUMPRODUCT(($E$2:$E3<>"")*($G$2:$G3<>"")*($H$2:$H3<>"")*($Q$2:$Q3<>"")*($R$2:$R3<>"")),"0000")) -> MP-0002 | B3: =IF($A3="","",GRUPO_NOMBRE) -> MATERIA PRIMA | C3: AVIOS DE CONFECCION | D3: CIERRES YKKA | E3: CIERRE METALICO 8 cm AZUL YKK | F3: Cierre metalico 10 cm Azul | G3: UND | H3: Nada | I3: =IF($C3="","",IFERROR(INDEX(CAT_CV,MATCH($C3,CAT_NOMBRE,0)),"")) -> CV-02 | Q3: Gravado - Operación Onerosa (18%) | R3: Activo
A4: =IF(OR($E4="",$G4="",$H4="",$Q4="",$R4=""),"",PREFIJO&TEXT(SUMPRODUCT(($E$2:$E4<>"")*($G$2:$G4<>"")*($H$2:$H4<>"")*($Q$2:$Q4<>"")*($R$2:$R4<>"")),"0000")) -> MP-0003 | B4: =IF($A4="","",GRUPO_NOMBRE) -> MATERIA PRIMA | C4: AVIOS DE CONFECCION | D4: CIERRES YKKA | E4: CIERRE METALICO 10 cm AZUL YKK | F4: Cierre metalico 10 cm Azul | G4: UND | H4: Nada | I4: =IF($C4="","",IFERROR(INDEX(CAT_CV,MATCH($C4,CAT_NOMBRE,0)),"")) -> CV-02 | Q4: Gravado - Operación Onerosa (18%) | R4: Activo
A5: =IF(OR($E5="",$G5="",$H5="",$Q5="",$R5=""),"",PREFIJO&TEXT(SUMPRODUCT(($E$2:$E5<>"")*($G$2:$G5<>"")*($H$2:$H5<>"")*($Q$2:$Q5<>"")*($R$2:$R5<>"")),"0000")) -> MP-0004 | B5: MATERIA PRIMA | C5: AVIOS DE CONFECCION | D5: CIERRES YKKA | E5: CIERRE METALICO 12 cm AZUL YKK | F5: Cierre metalico 12 cm Azul | G5: UND | H5: Nada | I5: =IF($C5="","",IFERROR(INDEX(CAT_CV,MATCH($C5,CAT_NOMBRE,0)),"")) -> CV-02 | Q5: Gravado - Operación Onerosa (18%) | R5: Activo
A6: =IF(OR($E6="",$G6="",$H6="",$Q6="",$R6=""),"",PREFIJO&TEXT(SUMPRODUCT(($E$2:$E6<>"")*($G$2:$G6<>"")*($H$2:$H6<>"")*($Q$2:$Q6<>"")*($R$2:$R6<>"")),"0000")) -> MP-0005 | B6: MATERIA PRIMA | C6: AVIOS DE CONFECCION | D6: CIERRES YKKA | E6: CIERRE METALICO 13 cm AZUL YKK | F6: Cierre metalico 13 cm Azul | G6: UND | H6: Nada | I6: =IF($C6="","",IFERROR(INDEX(CAT_CV,MATCH($C6,CAT_NOMBRE,0)),"")) -> CV-02 | Q6: Gravado - Operación Onerosa (18%) | R6: Activo
A7: =IF(OR($E7="",$G7="",$H7="",$Q7="",$R7=""),"",PREFIJO&TEXT(SUMPRODUCT(($E$2:$E7<>"")*($G$2:$G7<>"")*($H$2:$H7<>"")*($Q$2:$Q7<>"")*($R$2:$R7<>"")),"0000")) -> MP-0006 | B7: MATERIA PRIMA | C7: AVIOS DE CONFECCION | D7: CIERRES YKKA | E7: CIERRE METALICO 14 cm AZUL YKK | F7: Cierre metalico 14 cm Azul | G7: UND | H7: Nada | I7: =IF($C7="","",IFERROR(INDEX(CAT_CV,MATCH($C7,CAT_NOMBRE,0)),"")) -> CV-02 | Q7: Gravado - Operación Onerosa (18%) | R7: Activo
A8: =IF(OR($E8="",$G8="",$H8="",$Q8="",$R8=""),"",PREFIJO&TEXT(SUMPRODUCT(($E$2:$E8<>"")*($G$2:$G8<>"")*($H$2:$H8<>"")*($Q$2:$Q8<>"")*($R$2:$R8<>"")),"0000")) -> MP-0007 | B8: MATERIA PRIMA | C8: AVIOS DE CONFECCION | D8: CIERRES YKKA | E8: CIERRE METALICO 15 cm AZUL YKK | F8: Cierre metalico 15 cm Azul | G8: UND | H8: Nada | I8: =IF($C8="","",IFERROR(INDEX(CAT_CV,MATCH($C8,CAT_NOMBRE,0)),"")) -> CV-02 | Q8: Gravado - Operación Onerosa (18%) | R8: Activo
A9: =IF(OR($E9="",$G9="",$H9="",$Q9="",$R9=""),"",PREFIJO&TEXT(SUMPRODUCT(($E$2:$E9<>"")*($G$2:$G9<>"")*($H$2:$H9<>"")*($Q$2:$Q9<>"")*($R$2:$R9<>"")),"0000")) -> MP-0008 | B9: MATERIA PRIMA | C9: AVIOS DE CONFECCION | D9: CIERRES YKKN | E9: CIERRE METALICO 8 cm NEGRO YKK | F9: Cierre metalico 8 cm Negro | G9: UND | H9: Nada | Q9: Gravado - Operación Onerosa (18%) | R9: Activo
A10: =IF(OR($E10="",$G10="",$H10="",$Q10="",$R10=""),"",PREFIJO&TEXT(SUMPRODUCT(($E$2:$E10<>"")*($G$2:$G10<>"")*($H$2:$H10<>"")*($Q$2:$Q10<>"")*($R$2:$R10<>"")),"0000")) -> MP-0009 | B10: MATERIA PRIMA | C10: AVIOS DE CONFECCION | D10: CIERRES YKKN | E10: CIERRE METALICO 10 cm NEGRO YKK | F10: Cierre metalico 10 cm Negro | G10: UND | H10: Nada | Q10: Gravado - Operación Onerosa (18%) | R10: Activo
A11: =IF(OR($E11="",$G11="",$H11="",$Q11="",$R11=""),"",PREFIJO&TEXT(SUMPRODUCT(($E$2:$E11<>"")*($G$2:$G11<>"")*($H$2:$H11<>"")*($Q$2:$Q11<>"")*($R$2:$R11<>"")),"0000")) -> MP-0010 | B11: MATERIA PRIMA | C11: AVIOS DE CONFECCION | D11: CIERRES YKKN | E11: CIERRE METALICO 12 cm NEGRO YKK | F11: Cierre metalico 12 cm Negro | G11: UND | H11: Nada | I11: =IF($C11="","",IFERROR(INDEX(CAT_CV,MATCH($C11,CAT_NOMBRE,0)),"")) -> CV-02 | Q11: Gravado - Operación Onerosa (18%) | R11: Activo
A12: =IF(OR($E12="",$G12="",$H12="",$Q12="",$R12=""),"",PREFIJO&TEXT(SUMPRODUCT(($E$2:$E12<>"")*($G$2:$G12<>"")*($H$2:$H12<>"")*($Q$2:$Q12<>"")*($R$2:$R12<>"")),"0000")) -> MP-0011 | B12: MATERIA PRIMA | C12: AVIOS DE CONFECCION | D12: CIERRES YKKN | E12: CIERRE METALICO 13 cm NEGRO YKK | F12: Cierre metalico 13 cm Negro | G12: UND | H12: Nada | I12: =IF($C12="","",IFERROR(INDEX(CAT_CV,MATCH($C12,CAT_NOMBRE,0)),"")) -> CV-02 | Q12: Gravado - Operación Onerosa (18%) | R12: Activo
A13: =IF(OR($E13="",$G13="",$H13="",$Q13="",$R13=""),"",PREFIJO&TEXT(SUMPRODUCT(($E$2:$E13<>"")*($G$2:$G13<>"")*($H$2:$H13<>"")*($Q$2:$Q13<>"")*($R$2:$R13<>"")),"0000")) -> MP-0012 | B13: MATERIA PRIMA | C13: AVIOS DE CONFECCION | D13: CIERRES YKKN | E13: CIERRE METALICO 14 cm NEGRO YKK | F13: Cierre metalico 14 cm Negro | G13: UND | H13: Nada | Q13: Gravado - Operación Onerosa (18%) | R13: Activo
A14: =IF(OR($E14="",$G14="",$H14="",$Q14="",$R14=""),"",PREFIJO&TEXT(SUMPRODUCT(($E$2:$E14<>"")*($G$2:$G14<>"")*($H$2:$H14<>"")*($Q$2:$Q14<>"")*($R$2:$R14<>"")),"0000")) -> MP-0013 | B14: MATERIA PRIMA | C14: AVIOS DE CONFECCION | D14: CIERRES YKKN | E14: CIERRE METALICO 15 cm NEGRO YKK | F14: Cierre metalico 15 cm Negro | G14: UND | H14: Nada | Q14: Gravado - Operación Onerosa (18%) | R14: Activo
A15: =IF(OR($E15="",$G15="",$H15="",$Q15="",$R15=""),"",PREFIJO&TEXT(SUMPRODUCT(($E$2:$E15<>"")*($G$2:$G15<>"")*($H$2:$H15<>"")*($Q$2:$Q15<>"")*($R$2:$R15<>"")),"0000")) -> MP-0014 | B15: MATERIA PRIMA | C15: AVIOS DE CONFECCION | D15: CIERRES YKKN | E15: CIERRE METALICO 16 cm NEGRO YKK | F15: Cierre metalico 16 cm Negro | G15: UND | H15: Nada | Q15: Gravado - Operación Onerosa (18%) | R15: Activo
A16: =IF(OR($E16="",$G16="",$H16="",$Q16="",$R16=""),"",PREFIJO&TEXT(SUMPRODUCT(($E$2:$E16<>"")*($G$2:$G16<>"")*($H$2:$H16<>"")*($Q$2:$Q16<>"")*($R$2:$R16<>"")),"0000")) -> MP-0015 | B16: MATERIA PRIMA | C16: AVIOS DE CONFECCION | D16: CIERRES REY | E16: CIERRE METALICO 7 cm AZUL REY | F16: Cierre metalico 7 cm Azul Rey | G16: UND | H16: Nada | I16: =IF($C16="","",IFERROR(INDEX(CAT_CV,MATCH($C16,CAT_NOMBRE,0)),"")) -> CV-02 | Q16: Gravado - Operación Onerosa (18%) | R16: Activo
A17: =IF(OR($E17="",$G17="",$H17="",$Q17="",$R17=""),"",PREFIJO&TEXT(SUMPRODUCT(($E$2:$E17<>"")*($G$2:$G17<>"")*($H$2:$H17<>"")*($Q$2:$Q17<>"")*($R$2:$R17<>"")),"0000")) -> MP-0016 | B17: MATERIA PRIMA | C17: AVIOS DE CONFECCION | D17: CIERRES REY | E17: CIERRE METALICO 10 cm AZUL REY | F17: Cierre metalico 10 cm Azul Rey | G17: UND | H17: Nada | I17: =IF($C17="","",IFERROR(INDEX(CAT_CV,MATCH($C17,CAT_NOMBRE,0)),"")) -> CV-02 | Q17: Gravado - Operación Onerosa (18%) | R17: Activo
A18: =IF(OR($E18="",$G18="",$H18="",$Q18="",$R18=""),"",PREFIJO&TEXT(SUMPRODUCT(($E$2:$E18<>"")*($G$2:$G18<>"")*($H$2:$H18<>"")*($Q$2:$Q18<>"")*($R$2:$R18<>"")),"0000")) -> MP-0017 | B18: MATERIA PRIMA | C18: AVIOS DE CONFECCION | D18: CIERRES REY | E18: CIERRE METALICO 12 cm AZUL REY | F18: Cierre metalico 12 cm Azul Rey | G18: UND | H18: Nada | I18: =IF($C18="","",IFERROR(INDEX(CAT_CV,MATCH($C18,CAT_NOMBRE,0)),"")) -> CV-02 | Q18: Gravado - Operación Onerosa (18%) | R18: Activo
A19: =IF(OR($E19="",$G19="",$H19="",$Q19="",$R19=""),"",PREFIJO&TEXT(SUMPRODUCT(($E$2:$E19<>"")*($G$2:$G19<>"")*($H$2:$H19<>"")*($Q$2:$Q19<>"")*($R$2:$R19<>"")),"0000")) -> MP-0018 | B19: MATERIA PRIMA | C19: AVIOS DE CONFECCION | D19: CIERRES REY | E19: CIERRE METALICO 13 cm AZUL REY | F19: Cierre metalico 13 cm Azul Rey | G19: UND | H19: Nada | I19: =IF($C19="","",IFERROR(INDEX(CAT_CV,MATCH($C19,CAT_NOMBRE,0)),"")) -> CV-02 | Q19: Gravado - Operación Onerosa (18%) | R19: Activo
A20: =IF(OR($E20="",$G20="",$H20="",$Q20="",$R20=""),"",PREFIJO&TEXT(SUMPRODUCT(($E$2:$E20<>"")*($G$2:$G20<>"")*($H$2:$H20<>"")*($Q$2:$Q20<>"")*($R$2:$R20<>"")),"0000")) -> MP-0019 | B20: MATERIA PRIMA | C20: AVIOS DE CONFECCION | D20: CIERRES REY | E20: CIERRE METALICO 14 cm AZUL REY | F20: Cierre metalico 14 cm Azul Rey | G20: UND | H20: Nada | I20: =IF($C20="","",IFERROR(INDEX(CAT_CV,MATCH($C20,CAT_NOMBRE,0)),"")) -> CV-02 | Q20: Gravado - Operación Onerosa (18%) | R20: Activo | T20: YKK | U20: 10 | V20: AZUL | W20: =CONCATENATE(T20," ",U20," ",V20," ") -> YKK 10 AZUL
A21: =IF(OR($E21="",$G21="",$H21="",$Q21="",$R21=""),"",PREFIJO&TEXT(SUMPRODUCT(($E$2:$E21<>"")*($G$2:$G21<>"")*($H$2:$H21<>"")*($Q$2:$Q21<>"")*($R$2:$R21<>"")),"0000")) -> MP-0020 | B21: MATERIA PRIMA | C21: AVIOS DE CONFECCION | D21: CIERRES REY | E21: CIERRE METALICO 15 cm AZUL REY | F21: Cierre metalico 15 cm Azul Rey | G21: UND | H21: Nada | I21: =IF($C21="","",IFERROR(INDEX(CAT_CV,MATCH($C21,CAT_NOMBRE,0)),"")) -> CV-02 | Q21: Gravado - Operación Onerosa (18%) | R21: Activo | T21: YKK | U21: 12 | V21: AZUL | W21: =CONCATENATE(T21," ",U21," ",V21," ") -> YKK 12 AZUL
A22: =IF(OR($E22="",$G22="",$H22="",$Q22="",$R22=""),"",PREFIJO&TEXT(SUMPRODUCT(($E$2:$E22<>"")*($G$2:$G22<>"")*($H$2:$H22<>"")*($Q$2:$Q22<>"")*($R$2:$R22<>"")),"0000")) -> MP-0021 | B22: MATERIA PRIMA | C22: AVIOS DE CONFECCION | D22: CIERRES REY | E22: CIERRE METALICO 16 cm AZUL REY | F22: Cierre metalico 16 cm Azul Rey | G22: UND | H22: Nada | I22: =IF($C22="","",IFERROR(INDEX(CAT_CV,MATCH($C22,CAT_NOMBRE,0)),"")) -> CV-02 | Q22: Gravado - Operación Onerosa (18%) | R22: Activo
A23: =IF(OR($E23="",$G23="",$H23="",$Q23="",$R23=""),"",PREFIJO&TEXT(SUMPRODUCT(($E$2:$E23<>"")*($G$2:$G23<>"")*($H$2:$H23<>"")*($Q$2:$Q23<>"")*($R$2:$R23<>"")),"0000")) -> MP-0022 | B23: MATERIA PRIMA | C23: AVIOS DE CONFECCION | D23: CIERRES REY | E23: CIERRE METALICO 13 cm NEGRO REY | F23: Cierre metalico 13 cm Negro Rey | G23: UND | H23: Nada | I23: =IF($C23="","",IFERROR(INDEX(CAT_CV,MATCH($C23,CAT_NOMBRE,0)),"")) -> CV-02 | Q23: Gravado - Operación Onerosa (18%) | R23: Activo
A24: =IF(OR($E24="",$G24="",$H24="",$Q24="",$R24=""),"",PREFIJO&TEXT(SUMPRODUCT(($E$2:$E24<>"")*($G$2:$G24<>"")*($H$2:$H24<>"")*($Q$2:$Q24<>"")*($R$2:$R24<>"")),"0000")) -> MP-0023 | B24: MATERIA PRIMA | C24: AVIOS DE CONFECCION | D24: CIERRES REY | E24: CIERRE METALICO 14 cm NEGRO REY | F24: Cierre metalico 14 cm Negro Rey | G24: UND | H24: Nada | I24: =IF($C24="","",IFERROR(INDEX(CAT_CV,MATCH($C24,CAT_NOMBRE,0)),"")) -> CV-02 | Q24: Gravado - Operación Onerosa (18%) | R24: Activo
A25: =IF(OR($E25="",$G25="",$H25="",$Q25="",$R25=""),"",PREFIJO&TEXT(SUMPRODUCT(($E$2:$E25<>"")*($G$2:$G25<>"")*($H$2:$H25<>"")*($Q$2:$Q25<>"")*($R$2:$R25<>"")),"0000")) -> MP-0024 | B25: MATERIA PRIMA | C25: AVIOS DE CONFECCION | D25: CIERRES YKKB | E25: CIERRE METALICO 10 cm BLANCO YKK | F25: Cierre metalico 10 cm Blanco Ykkb | G25: UND | H25: Nada | I25: =IF($C25="","",IFERROR(INDEX(CAT_CV,MATCH($C25,CAT_NOMBRE,0)),"")) -> CV-02 | Q25: Gravado - Operación Onerosa (18%) | R25: Activo
A26: =IF(OR($E26="",$G26="",$H26="",$Q26="",$R26=""),"",PREFIJO&TEXT(SUMPRODUCT(($E$2:$E26<>"")*($G$2:$G26<>"")*($H$2:$H26<>"")*($Q$2:$Q26<>"")*($R$2:$R26<>"")),"0000")) -> MP-0025 | B26: MATERIA PRIMA | C26: AVIOS DE CONFECCION | D26: CIERRES YKKB | E26: CIERRE METALICO 12 cm BLANCO YKK | F26: Cierre metalico 12 cm Blanco Ykkb | G26: UND | H26: Nada | I26: =IF($C26="","",IFERROR(INDEX(CAT_CV,MATCH($C26,CAT_NOMBRE,0)),"")) -> CV-02 | Q26: Gravado - Operación Onerosa (18%) | R26: Activo
A27: =IF(OR($E27="",$G27="",$H27="",$Q27="",$R27=""),"",PREFIJO&TEXT(SUMPRODUCT(($E$2:$E27<>"")*($G$2:$G27<>"")*($H$2:$H27<>"")*($Q$2:$Q27<>"")*($R$2:$R27<>"")),"0000")) -> MP-0026 | B27: MATERIA PRIMA | C27: AVIOS DE CONFECCION | D27: CIERRES YKKB | E27: CIERRE METALICO 14 cm BLANCO YKK | F27: Cierre metalico 14 cm Blanco Ykkb | G27: UND | H27: Nada | I27: =IF($C27="","",IFERROR(INDEX(CAT_CV,MATCH($C27,CAT_NOMBRE,0)),"")) -> CV-02 | Q27: Gravado - Operación Onerosa (18%) | R27: Activo
A28: =IF(OR($E28="",$G28="",$H28="",$Q28="",$R28=""),"",PREFIJO&TEXT(SUMPRODUCT(($E$2:$E28<>"")*($G$2:$G28<>"")*($H$2:$H28<>"")*($Q$2:$Q28<>"")*($R$2:$R28<>"")),"0000")) -> MP-0027 | B28: MATERIA PRIMA | C28: AVIOS DE CONFECCION | D28: CIERRES YKKB | E28: CIERRE METALICO 15 cm BLANCO YKK | F28: Cierre metalico 15 cm Blanco Ykkb | G28: UND | H28: Nada | I28: =IF($C28="","",IFERROR(INDEX(CAT_CV,MATCH($C28,CAT_NOMBRE,0)),"")) -> CV-02 | Q28: Gravado - Operación Onerosa (18%) | R28: Activo
A29: =IF(OR($E29="",$G29="",$H29="",$Q29="",$R29=""),"",PREFIJO&TEXT(SUMPRODUCT(($E$2:$E29<>"")*($G$2:$G29<>"")*($H$2:$H29<>"")*($Q$2:$Q29<>"")*($R$2:$R29<>"")),"0000")) -> MP-0028 | B29: MATERIA PRIMA | C29: AVIOS DE CONFECCION | D29: CIERRES YKKC | E29: CIERRE METALICO 8 cm CELESTE YKK | F29: Cierre metalico 8 cm Celeste Ykkc | G29: UND | H29: Nada | I29: =IF($C29="","",IFERROR(INDEX(CAT_CV,MATCH($C29,CAT_NOMBRE,0)),"")) -> CV-02 | Q29: Gravado - Operación Onerosa (18%) | R29: Activo
A30: =IF(OR($E30="",$G30="",$H30="",$Q30="",$R30=""),"",PREFIJO&TEXT(SUMPRODUCT(($E$2:$E30<>"")*($G$2:$G30<>"")*($H$2:$H30<>"")*($Q$2:$Q30<>"")*($R$2:$R30<>"")),"0000")) -> MP-0029 | B30: MATERIA PRIMA | C30: AVIOS DE CONFECCION | D30: CIERRES YKKC | E30: CIERRE METALICO 10 cm CELESTE YKK | F30: Cierre metalico 10 cm Celeste Ykkc | G30: UND | H30: Nada | I30: =IF($C30="","",IFERROR(INDEX(CAT_CV,MATCH($C30,CAT_NOMBRE,0)),"")) -> CV-02 | Q30: Gravado - Operación Onerosa (18%) | R30: Activo
A31: =IF(OR($E31="",$G31="",$H31="",$Q31="",$R31=""),"",PREFIJO&TEXT(SUMPRODUCT(($E$2:$E31<>"")*($G$2:$G31<>"")*($H$2:$H31<>"")*($Q$2:$Q31<>"")*($R$2:$R31<>"")),"0000")) -> MP-0030 | B31: MATERIA PRIMA | C31: AVIOS DE CONFECCION | D31: CIERRES YKKC | E31: CIERRE METALICO 12 cm CELESTE YKK | F31: Cierre metalico 12 cm Celeste Ykkc | G31: UND | H31: Nada | I31: =IF($C31="","",IFERROR(INDEX(CAT_CV,MATCH($C31,CAT_NOMBRE,0)),"")) -> CV-02 | Q31: Gravado - Operación Onerosa (18%) | R31: Activo
A32: =IF(OR($E32="",$G32="",$H32="",$Q32="",$R32=""),"",PREFIJO&TEXT(SUMPRODUCT(($E$2:$E32<>"")*($G$2:$G32<>"")*($H$2:$H32<>"")*($Q$2:$Q32<>"")*($R$2:$R32<>"")),"0000")) -> MP-0031 | B32: MATERIA PRIMA | C32: AVIOS DE CONFECCION | D32: CIERRES YKKC | E32: CIERRE METALICO 13 cm CELESTE YKK | F32: Cierre metalico 13 cm Celeste Ykkc | G32: UND | H32: Nada | I32: =IF($C32="","",IFERROR(INDEX(CAT_CV,MATCH($C32,CAT_NOMBRE,0)),"")) -> CV-02 | Q32: Gravado - Operación Onerosa (18%) | R32: Activo
A33: =IF(OR($E33="",$G33="",$H33="",$Q33="",$R33=""),"",PREFIJO&TEXT(SUMPRODUCT(($E$2:$E33<>"")*($G$2:$G33<>"")*($H$2:$H33<>"")*($Q$2:$Q33<>"")*($R$2:$R33<>"")),"0000")) -> MP-0032 | B33: MATERIA PRIMA | C33: AVIOS DE CONFECCION | D33: CIERRES YKKC | E33: CIERRE METALICO 14 cm CELESTE YKK | F33: Cierre metalico 14 cm Celeste Ykkc | G33: UND | H33: Nada | I33: =IF($C33="","",IFERROR(INDEX(CAT_CV,MATCH($C33,CAT_NOMBRE,0)),"")) -> CV-02 | Q33: Gravado - Operación Onerosa (18%) | R33: Activo
... A46: =IF(OR($E46="",$G46="",$H46="",$Q46="",$R46=""),"",PREFIJO&TEXT(SUMPRODUCT(($E$2:$E46<>"")*($G$2:$G46<>"")*($H$2:$H46<>"")*($Q$2:$Q46<>"")*($R$2:$R46<>"")),"0000")) -> MP-0045 | B46: MATERIA PRIMA | C46: AVIOS DE CONFECCION | D46: TALLITAS | E46: TALLITA BLANCA N° 34 | F46: Tallitas Blancas N° 34 | G46: UND | H46: Nada | I46: =IF($C46="","",IFERROR(INDEX(CAT_CV,MATCH($C46,CAT_NOMBRE,0)),"")) -> CV-02 | Q46: Gravado - Operación Onerosa (18%) | R46: Activo
A47: =IF(OR($E47="",$G47="",$H47="",$Q47="",$R47=""),"",PREFIJO&TEXT(SUMPRODUCT(($E$2:$E47<>"")*($G$2:$G47<>"")*($H$2:$H47<>"")*($Q$2:$Q47<>"")*($R$2:$R47<>"")),"0000")) -> MP-0046 | B47: MATERIA PRIMA | C47: HILOS | E47: HILO BLANCO 20/2 | F47: Hilo Blanco 20/2 | G47: UND | H47: Nada | I47: =IF($C47="","",IFERROR(INDEX(CAT_CV,MATCH($C47,CAT_NOMBRE,0)),"")) -> CV-02 | Q47: Gravado - Operación Onerosa (18%) | R47: Activo
A48: =IF(OR($E48="",$G48="",$H48="",$Q48="",$R48=""),"",PREFIJO&TEXT(SUMPRODUCT(($E$2:$E48<>"")*($G$2:$G48<>"")*($H$2:$H48<>"")*($Q$2:$Q48<>"")*($R$2:$R48<>"")),"0000")) -> MP-0047 | B48: MATERIA PRIMA | C48: HILOS | E48: HILO BLANCO 20/3 | F48: Hilo Blanco 20/3 | G48: UND | H48: Nada | I48: =IF($C48="","",IFERROR(INDEX(CAT_CV,MATCH($C48,CAT_NOMBRE,0)),"")) -> CV-02 | Q48: Gravado - Operación Onerosa (18%) | R48: Activo
A49: =IF(OR($E49="",$G49="",$H49="",$Q49="",$R49=""),"",PREFIJO&TEXT(SUMPRODUCT(($E$2:$E49<>"")*($G$2:$G49<>"")*($H$2:$H49<>"")*($Q$2:$Q49<>"")*($R$2:$R49<>"")),"0000")) -> MP-0048 | B49: MATERIA PRIMA | C49: HILOS | E49: HILO BLANCO 40/2 | F49: Hilo Blanco 40/2 | G49: UND | H49: Nada | Q49: Gravado - Operación Onerosa (18%) | R49: Activo
A50: =IF(OR($E50="",$G50="",$H50="",$Q50="",$R50=""),"",PREFIJO&TEXT(SUMPRODUCT(($E$2:$E50<>"")*($G$2:$G50<>"")*($H$2:$H50<>"")*($Q$2:$Q50<>"")*($R$2:$R50<>"")),"0000")) -> MP-0049 | B50: MATERIA PRIMA | C50: HILOS | E50: HILO BEIGE 13 20/2 | F50: Hilo Beige 13 20/2 | G50: UND | H50: Nada | I50: =IF($C50="","",IFERROR(INDEX(CAT_CV,MATCH($C50,CAT_NOMBRE,0)),"")) -> CV-02 | Q50: Gravado - Operación Onerosa (18%) | R50: Activo
A51: =IF(OR($E51="",$G51="",$H51="",$Q51="",$R51=""),"",PREFIJO&TEXT(SUMPRODUCT(($E$2:$E51<>"")*($G$2:$G51<>"")*($H$2:$H51<>"")*($Q$2:$Q51<>"")*($R$2:$R51<>"")),"0000")) -> MP-0050 | B51: MATERIA PRIMA | C51: HILOS | E51: HILO BEIGE 13 20/3 | F51: Hilo Beige 13 20/3 | G51: UND | H51: Nada | I51: =IF($C51="","",IFERROR(INDEX(CAT_CV,MATCH($C51,CAT_NOMBRE,0)),"")) -> CV-02 | Q51: Gravado - Operación Onerosa (18%) | R51: Activo
A52: =IF(OR($E52="",$G52="",$H52="",$Q52="",$R52=""),"",PREFIJO&TEXT(SUMPRODUCT(($E$2:$E52<>"")*($G$2:$G52<>"")*($H$2:$H52<>"")*($Q$2:$Q52<>"")*($R$2:$R52<>"")),"0000")) -> MP-0051 | B52: MATERIA PRIMA | C52: HILOS | E52: HILO BEIGE 13 40/2 | F52: Hilo Beige 13 40/2 | G52: UND | H52: Nada | Q52: Gravado - Operación Onerosa (18%) | R52: Activo
...

Sheet Atributos
A2: Código artículo (*) | B2: Nombre artículo (auto) | C2: Atributo (*) | D2: Valor de Atributo (*)
B3: =IF($A3="","",IFERROR(INDEX(Artículos!$E$2:$E$213,MATCH($A3,Artículos!$A$2:$A$213,0)),""))
B4: =IF($A4="","",IFERROR(INDEX(Artículos!$E$2:$E$213,MATCH($A4,Artículos!$A$2:$A$213,0)),""))
B5: =IF($A5="","",IFERROR(INDEX(Artículos!$E$2:$E$213,MATCH($A5,Artículos!$A$2:$A$213,0)),""))
B6: =IF($A6="","",IFERROR(INDEX(Artículos!$E$2:$E$213,MATCH($A6,Artículos!$A$2:$A$213,0)),""))
B7: =IF($A7="","",IFERROR(INDEX(Artículos!$E$2:$E$213,MATCH($A7,Artículos!$A$2:$A$213,0)),""))
B8: =IF($A8="","",IFERROR(INDEX(Artículos!$E$2:$E$213,MATCH($A8,Artículos!$A$2:$A$213,0)),""))
B9: =IF($A9="","",IFERROR(INDEX(Artículos!$E$2:$E$213,MATCH($A9,Artículos!$A$2:$A$213,0)),""))
B10: =IF($A10="","",IFERROR(INDEX(Artículos!$E$2:$E$213,MATCH($A10,Artículos!$A$2:$A$213,0)),""))
B11: =IF($A11="","",IFERROR(INDEX(Artículos!$E$2:$E$213,MATCH($A11,Artículos!$A$2:$A$213,0)),""))
B12: =IF($A12="","",IFERROR(INDEX(Artículos!$E$2:$E$213,MATCH($A12,Artículos!$A$2:$A$213,0)),""))
B13: =IF($A13="","",IFERROR(INDEX(Artículos!$E$2:$E$213,MATCH($A13,Artículos!$A$2:$A$213,0)),""))
B14: =IF($A14="","",IFERROR(INDEX(Artículos!$E$2:$E$213,MATCH($A14,Artículos!$A$2:$A$213,0)),""))
... B122: =IF($A122="","",IFERROR(INDEX(Artículos!$E$2:$E$213,MATCH($A122,Artículos!$A$2:$A$213,0)),""))

Sheet Stock Mínimo
A2: Código artículo (*) | B2: Nombre artículo (auto) | C2: Código almacén (*) | D2: Nombre almacén (auto) | E2: Sede (auto) | F2: Cantidad mínima (*) | G2: Unidad (auto)
B3: =IF($A3="","",IFERROR(INDEX(Artículos!$E$2:$E$213,MATCH($A3,Artículos!$A$2:$A$213,0)),"")) | D3: =IF($C3="","",IFERROR(INDEX(ALM_NOM,MATCH($C3,ALM_COD,0)),"")) | E3: =IF($C3="","",IFERROR(INDEX(ALM_SEDE,MATCH($C3,ALM_COD,0)),"")) | G3: =IF($A3="","",IFERROR(INDEX(Artículos!$G$2:$G$213,MATCH($A3,Artículos!$A$2:$A$213,0)),""))
B4: =IF($A4="","",IFERROR(INDEX(Artículos!$E$2:$E$213,MATCH($A4,Artículos!$A$2:$A$213,0)),"")) | D4: =IF($C4="","",IFERROR(INDEX(ALM_NOM,MATCH($C4,ALM_COD,0)),"")) | E4: =IF($C4="","",IFERROR(INDEX(ALM_SEDE,MATCH($C4,ALM_COD,0)),"")) | G4: =IF($A4="","",IFERROR(INDEX(Artículos!$G$2:$G$213,MATCH($A4,Artículos!$A$2:$A$213,0)),""))
B5: =IF($A5="","",IFERROR(INDEX(Artículos!$E$2:$E$213,MATCH($A5,Artículos!$A$2:$A$213,0)),"")) | D5: =IF($C5="","",IFERROR(INDEX(ALM_NOM,MATCH($C5,ALM_COD,0)),"")) | E5: =IF($C5="","",IFERROR(INDEX(ALM_SEDE,MATCH($C5,ALM_COD,0)),"")) | G5: =IF($A5="","",IFERROR(INDEX(Artículos!$G$2:$G$213,MATCH($A5,Artículos!$A$2:$A$213,0)),""))
B6: =IF($A6="","",IFERROR(INDEX(Artículos!$E$2:$E$213,MATCH($A6,Artículos!$A$2:$A$213,0)),"")) | D6: =IF($C6="","",IFERROR(INDEX(ALM_NOM,MATCH($C6,ALM_COD,0)),"")) | E6: =IF($C6="","",IFERROR(INDEX(ALM_SEDE,MATCH($C6,ALM_COD,0)),"")) | G6: =IF($A6="","",IFERROR(INDEX(Artículos!$G$2:$G$213,MATCH($A6,Artículos!$A$2:$A$213,0)),""))
B7: =IF($A7="","",IFERROR(INDEX(Artículos!$E$2:$E$213,MATCH($A7,Artículos!$A$2:$A$213,0)),"")) | D7: =IF($C7="","",IFERROR(INDEX(ALM_NOM,MATCH($C7,ALM_COD,0)),"")) | E7: =IF($C7="","",IFERROR(INDEX(ALM_SEDE,MATCH($C7,ALM_COD,0)),"")) | G7: =IF($A7="","",IFERROR(INDEX(Artículos!$G$2:$G$213,MATCH($A7,Artículos!$A$2:$A$213,0)),""))
B8: =IF($A8="","",IFERROR(INDEX(Artículos!$E$2:$E$213,MATCH($A8,Artículos!$A$2:$A$213,0)),"")) | D8: =IF($C8="","",IFERROR(INDEX(ALM_NOM,MATCH($C8,ALM_COD,0)),"")) | E8: =IF($C8="","",IFERROR(INDEX(ALM_SEDE,MATCH($C8,ALM_COD,0)),"")) | G8: =IF($A8="","",IFERROR(INDEX(Artículos!$G$2:$G$213,MATCH($A8,Artículos!$A$2:$A$213,0)),""))
B9: =IF($A9="","",IFERROR(INDEX(Artículos!$E$2:$E$213,MATCH($A9,Artículos!$A$2:$A$213,0)),"")) | D9: =IF($C9="","",IFERROR(INDEX(ALM_NOM,MATCH($C9,ALM_COD,0)),"")) | E9: =IF($C9="","",IFERROR(INDEX(ALM_SEDE,MATCH($C9,ALM_COD,0)),"")) | G9: =IF($A9="","",IFERROR(INDEX(Artículos!$G$2:$G$213,MATCH($A9,Artículos!$A$2:$A$213,0)),""))
B10: =IF($A10="","",IFERROR(INDEX(Artículos!$E$2:$E$213,MATCH($A10,Artículos!$A$2:$A$213,0)),"")) | D10: =IF($C10="","",IFERROR(INDEX(ALM_NOM,MATCH($C10,ALM_COD,0)),"")) | E10: =IF($C10="","",IFERROR(INDEX(ALM_SEDE,MATCH($C10,ALM_COD,0)),"")) | G10: =IF($A10="","",IFERROR(INDEX(Artículos!$G$2:$G$213,MATCH($A10,Artículos!$A$2:$A$213,0)),""))
B11: =IF($A11="","",IFERROR(INDEX(Artículos!$E$2:$E$213,MATCH($A11,Artículos!$A$2:$A$213,0)),"")) | D11: =IF($C11="","",IFERROR(INDEX(ALM_NOM,MATCH($C11,ALM_COD,0)),"")) | E11: =IF($C11="","",IFERROR(INDEX(ALM_SEDE,MATCH($C11,ALM_COD,0)),"")) | G11: =IF($A11="","",IFERROR(INDEX(Artículos!$G$2:$G$213,MATCH($A11,Artículos!$A$2:$A$213,0)),""))
B12: =IF($A12="","",IFERROR(INDEX(Artículos!$E$2:$E$213,MATCH($A12,Artículos!$A$2:$A$213,0)),"")) | D12: =IF($C12="","",IFERROR(INDEX(ALM_NOM,MATCH($C12,ALM_COD,0)),"")) | E12: =IF($C12="","",IFERROR(INDEX(ALM_SEDE,MATCH($C12,ALM_COD,0)),"")) | G12: =IF($A12="","",IFERROR(INDEX(Artículos!$G$2:$G$213,MATCH($A12,Artículos!$A$2:$A$213,0)),""))
B13: =IF($A13="","",IFERROR(INDEX(Artículos!$E$2:$E$213,MATCH($A13,Artículos!$A$2:$A$213,0)),"")) | D13: =IF($C13="","",IFERROR(INDEX(ALM_NOM,MATCH($C13,ALM_COD,0)),"")) | E13: =IF($C13="","",IFERROR(INDEX(ALM_SEDE,MATCH($C13,ALM_COD,0)),"")) | G13: =IF($A13="","",IFERROR(INDEX(Artículos!$G$2:$G$213,MATCH($A13,Artículos!$A$2:$A$213,0)),""))
B14: =IF($A14="","",IFERROR(INDEX(Artículos!$E$2:$E$213,MATCH($A14,Artículos!$A$2:$A$213,0)),"")) | D14: =IF($C14="","",IFERROR(INDEX(ALM_NOM,MATCH($C14,ALM_COD,0)),"")) | E14: =IF($C14="","",IFERROR(INDEX(ALM_SEDE,MATCH($C14,ALM_COD,0)),"")) | G14: =IF($A14="","",IFERROR(INDEX(Artículos!$G$2:$G$213,MATCH($A14,Artículos!$A$2:$A$213,0)),""))
... B122: =IF($A122="","",IFERROR(INDEX(Artículos!$E$2:$E$213,MATCH($A122,Artículos!$A$2:$A$213,0)),"")) | D122: =IF($C122="","",IFERROR(INDEX(ALM_NOM,MATCH($C122,ALM_COD,0)),"")) | E122: =IF($C122="","",IFERROR(INDEX(ALM_SEDE,MATCH($C122,ALM_COD,0)),"")) | G122: =IF($A122="","",IFERROR(INDEX(Artículos!$G$2:$G$213,MATCH($A122,Artículos!$A$2:$A$213,0)),""))

Sheet Códigos de Barras
A2: Código artículo (*) | B2: Nombre artículo (auto) | C2: Tipo de código de barra (*) | D2: Código de barras (*) | E2: Observaciones
B3: =IF($A3="","",IFERROR(INDEX(Artículos!$E$2:$E$213,MATCH($A3,Artículos!$A$2:$A$213,0)),""))
B4: =IF($A4="","",IFERROR(INDEX(Artículos!$E$2:$E$213,MATCH($A4,Artículos!$A$2:$A$213,0)),""))
B5: =IF($A5="","",IFERROR(INDEX(Artículos!$E$2:$E$213,MATCH($A5,Artículos!$A$2:$A$213,0)),""))
B6: =IF($A6="","",IFERROR(INDEX(Artículos!$E$2:$E$213,MATCH($A6,Artículos!$A$2:$A$213,0)),""))
B7: =IF($A7="","",IFERROR(INDEX(Artículos!$E$2:$E$213,MATCH($A7,Artículos!$A$2:$A$213,0)),""))
B8: =IF($A8="","",IFERROR(INDEX(Artículos!$E$2:$E$213,MATCH($A8,Artículos!$A$2:$A$213,0)),""))
B9: =IF($A9="","",IFERROR(INDEX(Artículos!$E$2:$E$213,MATCH($A9,Artículos!$A$2:$A$213,0)),""))
B10: =IF($A10="","",IFERROR(INDEX(Artículos!$E$2:$E$213,MATCH($A10,Artículos!$A$2:$A$213,0)),""))
B11: =IF($A11="","",IFERROR(INDEX(Artículos!$E$2:$E$213,MATCH($A11,Artículos!$A$2:$A$213,0)),""))
B12: =IF($A12="","",IFERROR(INDEX(Artículos!$E$2:$E$213,MATCH($A12,Artículos!$A$2:$A$213,0)),""))
B13: =IF($A13="","",IFERROR(INDEX(Artículos!$E$2:$E$213,MATCH($A13,Artículos!$A$2:$A$213,0)),""))
B14: =IF($A14="","",IFERROR(INDEX(Artículos!$E$2:$E$213,MATCH($A14,Artículos!$A$2:$A$213,0)),""))
... B122: =IF($A122="","",IFERROR(INDEX(Artículos!$E$2:$E$213,MATCH($A122,Artículos!$A$2:$A$213,0)),""))

Sheet Configuraciones
B1: CONFIGURACIONES · GRUPO: MATERIA PRIMA
B4: 1. GRUPO DE ARTÍCULO (fijo en esta plantilla)
B5: Código | C5: Nombre | D5: Prefijo | E5: Asignación
B6: MP | C6: MATERIA PRIMA | D6: MP- | E6: Interna
B8: 2. CATEGORÍAS · código corto tipo prefijo (TEL, HIL, AVCONF…) (agrega filas debajo)
B9: CODIGO | C9: NOMBRE | D9: CV
B10: TEL | C10: TELAS | D10: CV-01
B11: HIL | C11: HILOS | D11: CV-02
B12: AVCONF | C12: AVIOS DE CONFECCION | D12: CV-02
B13: AVACABPRIN | C13: AVIOS DE ACABADOS PRINCIPALES | D13: CV-02
B14: AVACABSEC | C14: AVIOS DE ACABADOS SECUNDARIOS | D14: CV-02
B24: 3. SUB CATEGORÍAS · una tabla por categoría, sin código (agrega filas debajo)
B25: Categoría nueva con sub categorías: agrégala en el bloque 2, copia aquí uno de estos bloques y renombra la tabla como T_ + nombre con guiones bajos (Diseño de tabla → Nombre).
B26: TELAS
B27: SUBCATEGORIA
B28: RIGIDO
B29: CONFORT
B30: STRECH
B35: HILOS
B36: SUBCATEGORIA
B44: AVIOS DE CONFECCION
B45: SUBCATEGORIA
B46: CIERRES
... B182: 11. CLASES DE VALORIZACIÓN (solo referencia)
B183: Código | C183: Descripción
B184: CV-01 | C184: MP - Telas
B185: CV-02 | C185: MP - Avíos
B186: CV-03 | C186: MP - Envases y embalajes
B187: CV-04 | C187: PPT - En planta
B188: CV-05 | C188: PPT - En poder de terceros
B189: CV-06 | C189: Productos terminados
B190: CV-07 | C190: Mercadería
B191: CV-08 | C191: Muestras
B192: CV-09 | C192: Servicios
B195: 12. ALMACENES (referencia para Stock Mínimo · con su sede)
B196: CODIGO | C196: NOMBRE | D196: SEDE
B197: SB-CENTRAL | C197: Almacén Central | D197: Gamarra
B198: SB-CENTRAL-MP | C198: Almacén Central Materia Prima | D198: Gamarra
B199: SB-LIQUID | C199: Almacén Liquidación Central | D199: Gamarra
B200: SB-ZARATE-MP | C200: Almacén Zárate Materia Prima | D200: Zárate
...
