Workbook
Name LST_RECURSOS: OFFSET(Recursos!$A$2,0,0,MAX(COUNTIF(Recursos!$A$2:$A$201,"?*"),1),1)
Name PREFIJO_OPE: Configuraciones!$E$5
Name PREFIJO_REC: Configuraciones!$D$5
Name PROV_COD: OFFSET(Configuraciones!$B$69,0,0,MAX(COUNTA(Configuraciones!$B$69:$B$98),1),1)
Name PROV_NOM: OFFSET(Configuraciones!$C$69,0,0,MAX(COUNTA(Configuraciones!$B$69:$B$98),1),1)
Name TIPO_SERVICIO: Configuraciones!$F$5
Name TREC_CLASE: OFFSET(Configuraciones!$D$9,0,0,MAX(COUNTA(Configuraciones!$C$9:$C$20),1),1)
Name TREC_NOMBRE: OFFSET(Configuraciones!$C$9,0,0,MAX(COUNTA(Configuraciones!$C$9:$C$20),1),1)

Sheet 00 Guía
B1: GUÍA — PLANTILLA DE RECURSOS · PRODUCCIÓN (PR-11 / PR-12)
C3: LEYENDA DE COLORES
C4: Columna OBLIGATORIA (*) — debe llenarse siempre
C5: Columna OPCIONAL — llénala solo si aplica
C6: Columna AUTOMÁTICA — no la edites: se calcula sola
C7: Fila de EJEMPLO — sobrescríbela o bórrala
C9: CÓMO LLENAR (hoja Recursos)
C10: • Una fila por recurso desde la fila 2 (las filas 2 y 3 son ejemplos). No dejes filas vacías intermedias.
C11: • El CÓDIGO se genera SOLO cuando están completos los 6 obligatorios: Tipo de recurso, Nombre, Unidad de consumo, Costo estándar, Cuenta mayor y Estado. Mientras falte alguno, la celda queda vacía.
C12: • El Costo Estándar es por unidad de consumo (S/. por HORA, por DÍA, por UND…). La Cuenta Mayor es solo números (ej. 921101).
C14: SERVICIOS DE TERCEROS — un servicio se da de alta UNA sola vez (decisiones O1–O5)
C15: • El servicio NACE como ARTÍCULO del grupo SRV, en PLANTILLA_Articulos_SERVICIOS.xlsx. Aquí NO se crea un código nuevo: escribe su SRV-nnnn en «Artículo de servicio» y la columna Código lo copia tal cual.
C16: • Esta hoja solo le agrega lo que compras no tiene: costo estándar, cuenta mayor (921201) y proveedor habitual. El artículo SRV sirve para la OC y la factura; el recurso, para costear la orden de fabricación.
... C26: • Proveedores (bloque 7): lista de referencia usada solo por los recursos de tipo SERVICIO DE TERCEROS; el maestro real es la PLANTILLA_Proveedores.

Sheet Recursos
A1: Código (auto) | B1: Tipo de recurso (*) | C1: Clase (auto) | D1: Nombre (*) | E1: Descripción | F1: Unidad de consumo (*) | G1: Costo estándar S/. (*) | H1: Cuenta mayor (*) | K1: Nombre del proveedor (auto) | L1: Estado (*)
A2: =IF(OR($B2="",$D2="",$F2="",$G2="",$H2="",$L2=""),"",IF($B2=TIPO_SERVICIO,IF($I2="","",$I2),PREFIJO_REC&TEXT(SUMPRODUCT(($B$2:$B2<>TIPO_SERVICIO)*($B$2:$B2<>"")*($D$2:$D2<>"")*($F$2:$F2<>"")*($G$2:$G2<>"")*($H$2:$H2<>"")*($L$2:$L2<>"")),"0000"))) -> REC-0001 | B2: RECURSO HUMANO | C2: =IF($B2="","",IFERROR(INDEX(TREC_CLASE,MATCH($B2,TREC_NOMBRE,0)),"")) -> humano | D2: Operario de corte | E2: Mano de obra directa de corte | F2: HORA | G2: 15 | H2: 921101 | K2: =IF($J2="","",IFERROR(INDEX(PROV_NOM,MATCH($J2,PROV_COD,0)),"")) | L2: Activo
A3: =IF(OR($B3="",$D3="",$F3="",$G3="",$H3="",$L3=""),"",IF($B3=TIPO_SERVICIO,IF($I3="","",$I3),PREFIJO_REC&TEXT(SUMPRODUCT(($B$2:$B3<>TIPO_SERVICIO)*($B$2:$B3<>"")*($D$2:$D3<>"")*($F$2:$F3<>"")*($G$2:$G3<>"")*($H$2:$H3<>"")*($L$2:$L3<>"")),"0000"))) -> REC-0002 | B3: RECURSO HUMANO | C3: =IF($B3="","",IFERROR(INDEX(TREC_CLASE,MATCH($B3,TREC_NOMBRE,0)),"")) -> humano | D3: Operario de maquina | E3: Mano de obra directa de maquina | F3: HORA | G3: 15 | H3: 921201 | K3: =IF($J3="","",IFERROR(INDEX(PROV_NOM,MATCH($J3,PROV_COD,0)),"")) | L3: Activo
A4: =IF(OR($B4="",$D4="",$F4="",$G4="",$H4="",$L4=""),"",IF($B4=TIPO_SERVICIO,IF($I4="","",$I4),PREFIJO_REC&TEXT(SUMPRODUCT(($B$2:$B4<>TIPO_SERVICIO)*($B$2:$B4<>"")*($D$2:$D4<>"")*($F$2:$F4<>"")*($G$2:$G4<>"")*($H$2:$H4<>"")*($L$2:$L4<>"")),"0000"))) | C4: =IF($B4="","",IFERROR(INDEX(TREC_CLASE,MATCH($B4,TREC_NOMBRE,0)),"")) | K4: =IF($J4="","",IFERROR(INDEX(PROV_NOM,MATCH($J4,PROV_COD,0)),"")) | L4: Activo
A5: =IF(OR($B5="",$D5="",$F5="",$G5="",$H5="",$L5=""),"",IF($B5=TIPO_SERVICIO,IF($I5="","",$I5),PREFIJO_REC&TEXT(SUMPRODUCT(($B$2:$B5<>TIPO_SERVICIO)*($B$2:$B5<>"")*($D$2:$D5<>"")*($F$2:$F5<>"")*($G$2:$G5<>"")*($H$2:$H5<>"")*($L$2:$L5<>"")),"0000"))) | C5: =IF($B5="","",IFERROR(INDEX(TREC_CLASE,MATCH($B5,TREC_NOMBRE,0)),"")) | K5: =IF($J5="","",IFERROR(INDEX(PROV_NOM,MATCH($J5,PROV_COD,0)),"")) | L5: Activo
A6: =IF(OR($B6="",$D6="",$F6="",$G6="",$H6="",$L6=""),"",IF($B6=TIPO_SERVICIO,IF($I6="","",$I6),PREFIJO_REC&TEXT(SUMPRODUCT(($B$2:$B6<>TIPO_SERVICIO)*($B$2:$B6<>"")*($D$2:$D6<>"")*($F$2:$F6<>"")*($G$2:$G6<>"")*($H$2:$H6<>"")*($L$2:$L6<>"")),"0000"))) | C6: =IF($B6="","",IFERROR(INDEX(TREC_CLASE,MATCH($B6,TREC_NOMBRE,0)),"")) | K6: =IF($J6="","",IFERROR(INDEX(PROV_NOM,MATCH($J6,PROV_COD,0)),"")) | L6: Activo
A7: =IF(OR($B7="",$D7="",$F7="",$G7="",$H7="",$L7=""),"",IF($B7=TIPO_SERVICIO,IF($I7="","",$I7),PREFIJO_REC&TEXT(SUMPRODUCT(($B$2:$B7<>TIPO_SERVICIO)*($B$2:$B7<>"")*($D$2:$D7<>"")*($F$2:$F7<>"")*($G$2:$G7<>"")*($H$2:$H7<>"")*($L$2:$L7<>"")),"0000"))) | C7: =IF($B7="","",IFERROR(INDEX(TREC_CLASE,MATCH($B7,TREC_NOMBRE,0)),"")) | K7: =IF($J7="","",IFERROR(INDEX(PROV_NOM,MATCH($J7,PROV_COD,0)),"")) | L7: Activo
A8: =IF(OR($B8="",$D8="",$F8="",$G8="",$H8="",$L8=""),"",IF($B8=TIPO_SERVICIO,IF($I8="","",$I8),PREFIJO_REC&TEXT(SUMPRODUCT(($B$2:$B8<>TIPO_SERVICIO)*($B$2:$B8<>"")*($D$2:$D8<>"")*($F$2:$F8<>"")*($G$2:$G8<>"")*($H$2:$H8<>"")*($L$2:$L8<>"")),"0000"))) | C8: =IF($B8="","",IFERROR(INDEX(TREC_CLASE,MATCH($B8,TREC_NOMBRE,0)),"")) | K8: =IF($J8="","",IFERROR(INDEX(PROV_NOM,MATCH($J8,PROV_COD,0)),"")) | L8: Activo
A9: =IF(OR($B9="",$D9="",$F9="",$G9="",$H9="",$L9=""),"",IF($B9=TIPO_SERVICIO,IF($I9="","",$I9),PREFIJO_REC&TEXT(SUMPRODUCT(($B$2:$B9<>TIPO_SERVICIO)*($B$2:$B9<>"")*($D$2:$D9<>"")*($F$2:$F9<>"")*($G$2:$G9<>"")*($H$2:$H9<>"")*($L$2:$L9<>"")),"0000"))) | C9: =IF($B9="","",IFERROR(INDEX(TREC_CLASE,MATCH($B9,TREC_NOMBRE,0)),"")) | K9: =IF($J9="","",IFERROR(INDEX(PROV_NOM,MATCH($J9,PROV_COD,0)),"")) | L9: Activo
A10: =IF(OR($B10="",$D10="",$F10="",$G10="",$H10="",$L10=""),"",IF($B10=TIPO_SERVICIO,IF($I10="","",$I10),PREFIJO_REC&TEXT(SUMPRODUCT(($B$2:$B10<>TIPO_SERVICIO)*($B$2:$B10<>"")*($D$2:$D10<>"")*($F$2:$F10<>"")*($G$2:$G10<>"")*($H$2:$H10<>"")*($L$2:$L10<>"")),"0000"))) | C10: =IF($B10="","",IFERROR(INDEX(TREC_CLASE,MATCH($B10,TREC_NOMBRE,0)),"")) | K10: =IF($J10="","",IFERROR(INDEX(PROV_NOM,MATCH($J10,PROV_COD,0)),"")) | L10: Activo
A11: =IF(OR($B11="",$D11="",$F11="",$G11="",$H11="",$L11=""),"",IF($B11=TIPO_SERVICIO,IF($I11="","",$I11),PREFIJO_REC&TEXT(SUMPRODUCT(($B$2:$B11<>TIPO_SERVICIO)*($B$2:$B11<>"")*($D$2:$D11<>"")*($F$2:$F11<>"")*($G$2:$G11<>"")*($H$2:$H11<>"")*($L$2:$L11<>"")),"0000"))) | C11: =IF($B11="","",IFERROR(INDEX(TREC_CLASE,MATCH($B11,TREC_NOMBRE,0)),"")) | K11: =IF($J11="","",IFERROR(INDEX(PROV_NOM,MATCH($J11,PROV_COD,0)),"")) | L11: Activo
A12: =IF(OR($B12="",$D12="",$F12="",$G12="",$H12="",$L12=""),"",IF($B12=TIPO_SERVICIO,IF($I12="","",$I12),PREFIJO_REC&TEXT(SUMPRODUCT(($B$2:$B12<>TIPO_SERVICIO)*($B$2:$B12<>"")*($D$2:$D12<>"")*($F$2:$F12<>"")*($G$2:$G12<>"")*($H$2:$H12<>"")*($L$2:$L12<>"")),"0000"))) | C12: =IF($B12="","",IFERROR(INDEX(TREC_CLASE,MATCH($B12,TREC_NOMBRE,0)),"")) | K12: =IF($J12="","",IFERROR(INDEX(PROV_NOM,MATCH($J12,PROV_COD,0)),"")) | L12: Activo
A13: =IF(OR($B13="",$D13="",$F13="",$G13="",$H13="",$L13=""),"",IF($B13=TIPO_SERVICIO,IF($I13="","",$I13),PREFIJO_REC&TEXT(SUMPRODUCT(($B$2:$B13<>TIPO_SERVICIO)*($B$2:$B13<>"")*($D$2:$D13<>"")*($F$2:$F13<>"")*($G$2:$G13<>"")*($H$2:$H13<>"")*($L$2:$L13<>"")),"0000"))) | C13: =IF($B13="","",IFERROR(INDEX(TREC_CLASE,MATCH($B13,TREC_NOMBRE,0)),"")) | K13: =IF($J13="","",IFERROR(INDEX(PROV_NOM,MATCH($J13,PROV_COD,0)),"")) | L13: Activo
A14: =IF(OR($B14="",$D14="",$F14="",$G14="",$H14="",$L14=""),"",IF($B14=TIPO_SERVICIO,IF($I14="","",$I14),PREFIJO_REC&TEXT(SUMPRODUCT(($B$2:$B14<>TIPO_SERVICIO)*($B$2:$B14<>"")*($D$2:$D14<>"")*($F$2:$F14<>"")*($G$2:$G14<>"")*($H$2:$H14<>"")*($L$2:$L14<>"")),"0000"))) | C14: =IF($B14="","",IFERROR(INDEX(TREC_CLASE,MATCH($B14,TREC_NOMBRE,0)),"")) | K14: =IF($J14="","",IFERROR(INDEX(PROV_NOM,MATCH($J14,PROV_COD,0)),"")) | L14: Activo
A15: =IF(OR($B15="",$D15="",$F15="",$G15="",$H15="",$L15=""),"",IF($B15=TIPO_SERVICIO,IF($I15="","",$I15),PREFIJO_REC&TEXT(SUMPRODUCT(($B$2:$B15<>TIPO_SERVICIO)*($B$2:$B15<>"")*($D$2:$D15<>"")*($F$2:$F15<>"")*($G$2:$G15<>"")*($H$2:$H15<>"")*($L$2:$L15<>"")),"0000"))) | C15: =IF($B15="","",IFERROR(INDEX(TREC_CLASE,MATCH($B15,TREC_NOMBRE,0)),"")) | K15: =IF($J15="","",IFERROR(INDEX(PROV_NOM,MATCH($J15,PROV_COD,0)),"")) | L15: Activo
... A201: =IF(OR($B201="",$D201="",$F201="",$G201="",$H201="",$L201=""),"",IF($B201=TIPO_SERVICIO,IF($I201="","",$I201),PREFIJO_REC&TEXT(SUMPRODUCT(($B$2:$B201<>TIPO_SERVICIO)*($B$2:$B201<>"")*($D$2:$D201<>"")*($F$2:$F201<>"")*($G$2:$G201<>"")*($H$2:$H201<>"")*($L$2:$L201<>"")),"0000"))) | C201: =IF($B201="","",IFERROR(INDEX(TREC_CLASE,MATCH($B201,TREC_NOMBRE,0)),"")) | K201: =IF($J201="","",IFERROR(INDEX(PROV_NOM,MATCH($J201,PROV_COD,0)),"")) | L201: Activo

Sheet Operarios
A1: OPERARIOS — cada operario ocupa un recurso de la hoja Recursos
A2: Código (auto) | B2: Nombre (*) | C2: Código de recurso que ocupa (*) | D2: Nombre del recurso (auto) | E2: Tipo de recurso (auto) | F2: Unidad de consumo (auto) | G2: Costo estándar S/. (auto) | H2: Estado (*)
A3: =IF(OR($B3="",$C3="",$H3=""),"",PREFIJO_OPE&TEXT(SUMPRODUCT(($B$3:$B3<>"")*($C$3:$C3<>"")*($H$3:$H3<>"")),"000")) -> OPE-001 | B3: Luis Torres | C3: REC-0001 | D3: =IF($C3="","",IFERROR(INDEX(Recursos!$D$2:$D$201,MATCH($C3,Recursos!$A$2:$A$201,0)),"")) -> Operario de corte | E3: =IF($C3="","",IFERROR(INDEX(Recursos!$B$2:$B$201,MATCH($C3,Recursos!$A$2:$A$201,0)),"")) -> RECURSO HUMANO | F3: =IF($C3="","",IFERROR(INDEX(Recursos!$F$2:$F$201,MATCH($C3,Recursos!$A$2:$A$201,0)),"")) -> HORA | G3: =IF($C3="","",IFERROR(INDEX(Recursos!$G$2:$G$201,MATCH($C3,Recursos!$A$2:$A$201,0)),"")) -> 15 | H3: Activo
A4: =IF(OR($B4="",$C4="",$H4=""),"",PREFIJO_OPE&TEXT(SUMPRODUCT(($B$3:$B4<>"")*($C$3:$C4<>"")*($H$3:$H4<>"")),"000")) | D4: =IF($C4="","",IFERROR(INDEX(Recursos!$D$2:$D$201,MATCH($C4,Recursos!$A$2:$A$201,0)),"")) | E4: =IF($C4="","",IFERROR(INDEX(Recursos!$B$2:$B$201,MATCH($C4,Recursos!$A$2:$A$201,0)),"")) | F4: =IF($C4="","",IFERROR(INDEX(Recursos!$F$2:$F$201,MATCH($C4,Recursos!$A$2:$A$201,0)),"")) | G4: =IF($C4="","",IFERROR(INDEX(Recursos!$G$2:$G$201,MATCH($C4,Recursos!$A$2:$A$201,0)),"")) | H4: Activo
A5: =IF(OR($B5="",$C5="",$H5=""),"",PREFIJO_OPE&TEXT(SUMPRODUCT(($B$3:$B5<>"")*($C$3:$C5<>"")*($H$3:$H5<>"")),"000")) | D5: =IF($C5="","",IFERROR(INDEX(Recursos!$D$2:$D$201,MATCH($C5,Recursos!$A$2:$A$201,0)),"")) | E5: =IF($C5="","",IFERROR(INDEX(Recursos!$B$2:$B$201,MATCH($C5,Recursos!$A$2:$A$201,0)),"")) | F5: =IF($C5="","",IFERROR(INDEX(Recursos!$F$2:$F$201,MATCH($C5,Recursos!$A$2:$A$201,0)),"")) | G5: =IF($C5="","",IFERROR(INDEX(Recursos!$G$2:$G$201,MATCH($C5,Recursos!$A$2:$A$201,0)),"")) | H5: Activo
A6: =IF(OR($B6="",$C6="",$H6=""),"",PREFIJO_OPE&TEXT(SUMPRODUCT(($B$3:$B6<>"")*($C$3:$C6<>"")*($H$3:$H6<>"")),"000")) | D6: =IF($C6="","",IFERROR(INDEX(Recursos!$D$2:$D$201,MATCH($C6,Recursos!$A$2:$A$201,0)),"")) | E6: =IF($C6="","",IFERROR(INDEX(Recursos!$B$2:$B$201,MATCH($C6,Recursos!$A$2:$A$201,0)),"")) | F6: =IF($C6="","",IFERROR(INDEX(Recursos!$F$2:$F$201,MATCH($C6,Recursos!$A$2:$A$201,0)),"")) | G6: =IF($C6="","",IFERROR(INDEX(Recursos!$G$2:$G$201,MATCH($C6,Recursos!$A$2:$A$201,0)),"")) | H6: Activo
A7: =IF(OR($B7="",$C7="",$H7=""),"",PREFIJO_OPE&TEXT(SUMPRODUCT(($B$3:$B7<>"")*($C$3:$C7<>"")*($H$3:$H7<>"")),"000")) | D7: =IF($C7="","",IFERROR(INDEX(Recursos!$D$2:$D$201,MATCH($C7,Recursos!$A$2:$A$201,0)),"")) | E7: =IF($C7="","",IFERROR(INDEX(Recursos!$B$2:$B$201,MATCH($C7,Recursos!$A$2:$A$201,0)),"")) | F7: =IF($C7="","",IFERROR(INDEX(Recursos!$F$2:$F$201,MATCH($C7,Recursos!$A$2:$A$201,0)),"")) | G7: =IF($C7="","",IFERROR(INDEX(Recursos!$G$2:$G$201,MATCH($C7,Recursos!$A$2:$A$201,0)),"")) | H7: Activo
A8: =IF(OR($B8="",$C8="",$H8=""),"",PREFIJO_OPE&TEXT(SUMPRODUCT(($B$3:$B8<>"")*($C$3:$C8<>"")*($H$3:$H8<>"")),"000")) | D8: =IF($C8="","",IFERROR(INDEX(Recursos!$D$2:$D$201,MATCH($C8,Recursos!$A$2:$A$201,0)),"")) | E8: =IF($C8="","",IFERROR(INDEX(Recursos!$B$2:$B$201,MATCH($C8,Recursos!$A$2:$A$201,0)),"")) | F8: =IF($C8="","",IFERROR(INDEX(Recursos!$F$2:$F$201,MATCH($C8,Recursos!$A$2:$A$201,0)),"")) | G8: =IF($C8="","",IFERROR(INDEX(Recursos!$G$2:$G$201,MATCH($C8,Recursos!$A$2:$A$201,0)),"")) | H8: Activo
A9: =IF(OR($B9="",$C9="",$H9=""),"",PREFIJO_OPE&TEXT(SUMPRODUCT(($B$3:$B9<>"")*($C$3:$C9<>"")*($H$3:$H9<>"")),"000")) | D9: =IF($C9="","",IFERROR(INDEX(Recursos!$D$2:$D$201,MATCH($C9,Recursos!$A$2:$A$201,0)),"")) | E9: =IF($C9="","",IFERROR(INDEX(Recursos!$B$2:$B$201,MATCH($C9,Recursos!$A$2:$A$201,0)),"")) | F9: =IF($C9="","",IFERROR(INDEX(Recursos!$F$2:$F$201,MATCH($C9,Recursos!$A$2:$A$201,0)),"")) | G9: =IF($C9="","",IFERROR(INDEX(Recursos!$G$2:$G$201,MATCH($C9,Recursos!$A$2:$A$201,0)),"")) | H9: Activo
A10: =IF(OR($B10="",$C10="",$H10=""),"",PREFIJO_OPE&TEXT(SUMPRODUCT(($B$3:$B10<>"")*($C$3:$C10<>"")*($H$3:$H10<>"")),"000")) | D10: =IF($C10="","",IFERROR(INDEX(Recursos!$D$2:$D$201,MATCH($C10,Recursos!$A$2:$A$201,0)),"")) | E10: =IF($C10="","",IFERROR(INDEX(Recursos!$B$2:$B$201,MATCH($C10,Recursos!$A$2:$A$201,0)),"")) | F10: =IF($C10="","",IFERROR(INDEX(Recursos!$F$2:$F$201,MATCH($C10,Recursos!$A$2:$A$201,0)),"")) | G10: =IF($C10="","",IFERROR(INDEX(Recursos!$G$2:$G$201,MATCH($C10,Recursos!$A$2:$A$201,0)),"")) | H10: Activo
A11: =IF(OR($B11="",$C11="",$H11=""),"",PREFIJO_OPE&TEXT(SUMPRODUCT(($B$3:$B11<>"")*($C$3:$C11<>"")*($H$3:$H11<>"")),"000")) | D11: =IF($C11="","",IFERROR(INDEX(Recursos!$D$2:$D$201,MATCH($C11,Recursos!$A$2:$A$201,0)),"")) | E11: =IF($C11="","",IFERROR(INDEX(Recursos!$B$2:$B$201,MATCH($C11,Recursos!$A$2:$A$201,0)),"")) | F11: =IF($C11="","",IFERROR(INDEX(Recursos!$F$2:$F$201,MATCH($C11,Recursos!$A$2:$A$201,0)),"")) | G11: =IF($C11="","",IFERROR(INDEX(Recursos!$G$2:$G$201,MATCH($C11,Recursos!$A$2:$A$201,0)),"")) | H11: Activo
A12: =IF(OR($B12="",$C12="",$H12=""),"",PREFIJO_OPE&TEXT(SUMPRODUCT(($B$3:$B12<>"")*($C$3:$C12<>"")*($H$3:$H12<>"")),"000")) | D12: =IF($C12="","",IFERROR(INDEX(Recursos!$D$2:$D$201,MATCH($C12,Recursos!$A$2:$A$201,0)),"")) | E12: =IF($C12="","",IFERROR(INDEX(Recursos!$B$2:$B$201,MATCH($C12,Recursos!$A$2:$A$201,0)),"")) | F12: =IF($C12="","",IFERROR(INDEX(Recursos!$F$2:$F$201,MATCH($C12,Recursos!$A$2:$A$201,0)),"")) | G12: =IF($C12="","",IFERROR(INDEX(Recursos!$G$2:$G$201,MATCH($C12,Recursos!$A$2:$A$201,0)),"")) | H12: Activo
A13: =IF(OR($B13="",$C13="",$H13=""),"",PREFIJO_OPE&TEXT(SUMPRODUCT(($B$3:$B13<>"")*($C$3:$C13<>"")*($H$3:$H13<>"")),"000")) | D13: =IF($C13="","",IFERROR(INDEX(Recursos!$D$2:$D$201,MATCH($C13,Recursos!$A$2:$A$201,0)),"")) | E13: =IF($C13="","",IFERROR(INDEX(Recursos!$B$2:$B$201,MATCH($C13,Recursos!$A$2:$A$201,0)),"")) | F13: =IF($C13="","",IFERROR(INDEX(Recursos!$F$2:$F$201,MATCH($C13,Recursos!$A$2:$A$201,0)),"")) | G13: =IF($C13="","",IFERROR(INDEX(Recursos!$G$2:$G$201,MATCH($C13,Recursos!$A$2:$A$201,0)),"")) | H13: Activo
A14: =IF(OR($B14="",$C14="",$H14=""),"",PREFIJO_OPE&TEXT(SUMPRODUCT(($B$3:$B14<>"")*($C$3:$C14<>"")*($H$3:$H14<>"")),"000")) | D14: =IF($C14="","",IFERROR(INDEX(Recursos!$D$2:$D$201,MATCH($C14,Recursos!$A$2:$A$201,0)),"")) | E14: =IF($C14="","",IFERROR(INDEX(Recursos!$B$2:$B$201,MATCH($C14,Recursos!$A$2:$A$201,0)),"")) | F14: =IF($C14="","",IFERROR(INDEX(Recursos!$F$2:$F$201,MATCH($C14,Recursos!$A$2:$A$201,0)),"")) | G14: =IF($C14="","",IFERROR(INDEX(Recursos!$G$2:$G$201,MATCH($C14,Recursos!$A$2:$A$201,0)),"")) | H14: Activo
A15: =IF(OR($B15="",$C15="",$H15=""),"",PREFIJO_OPE&TEXT(SUMPRODUCT(($B$3:$B15<>"")*($C$3:$C15<>"")*($H$3:$H15<>"")),"000")) | D15: =IF($C15="","",IFERROR(INDEX(Recursos!$D$2:$D$201,MATCH($C15,Recursos!$A$2:$A$201,0)),"")) | E15: =IF($C15="","",IFERROR(INDEX(Recursos!$B$2:$B$201,MATCH($C15,Recursos!$A$2:$A$201,0)),"")) | F15: =IF($C15="","",IFERROR(INDEX(Recursos!$F$2:$F$201,MATCH($C15,Recursos!$A$2:$A$201,0)),"")) | G15: =IF($C15="","",IFERROR(INDEX(Recursos!$G$2:$G$201,MATCH($C15,Recursos!$A$2:$A$201,0)),"")) | H15: Activo
... A152: =IF(OR($B152="",$C152="",$H152=""),"",PREFIJO_OPE&TEXT(SUMPRODUCT(($B$3:$B152<>"")*($C$3:$C152<>"")*($H$3:$H152<>"")),"000")) | D152: =IF($C152="","",IFERROR(INDEX(Recursos!$D$2:$D$201,MATCH($C152,Recursos!$A$2:$A$201,0)),"")) | E152: =IF($C152="","",IFERROR(INDEX(Recursos!$B$2:$B$201,MATCH($C152,Recursos!$A$2:$A$201,0)),"")) | F152: =IF($C152="","",IFERROR(INDEX(Recursos!$F$2:$F$201,MATCH($C152,Recursos!$A$2:$A$201,0)),"")) | G152: =IF($C152="","",IFERROR(INDEX(Recursos!$G$2:$G$201,MATCH($C152,Recursos!$A$2:$A$201,0)),"")) | H152: Activo

Sheet Configuraciones
B1: CONFIGURACIONES · MAESTRO DE RECURSOS (PRODUCCIÓN)
B3: 1. MAESTRO (fijo en esta plantilla)
B4: MODULO | C4: MAESTRO | D4: PREFIJO RECURSO | E4: PREFIJO OPERARIO | F4: TIPO DE SERVICIO
B5: Producción | C5: RECURSOS | D5: REC- | E5: OPE- | F5: SERVICIO DE TERCEROS
B7: 2. TIPOS DE RECURSO · código TRC-nnnn (agrega filas debajo)
B8: CODIGO | C8: NOMBRE | D8: CLASE
B9: TRC-0001 | C9: RECURSO HUMANO | D9: humano
B10: TRC-0002 | C10: ACTIVOS FIJOS Y EXTRAS
B11: TRC-0003 | D11: servicio
B22: 3. UNIDADES DE CONSUMO (espacio amplio: agrega debajo)
B23: UNIDAD
B24: HORA
B25: DÍA
B26: UND
B27: MT
B28: KG
B29: DOC
B30: MILLAR
B31: PAR
B32: JUEGO
B33: CAJA
... B48: 5. CLASES DE TIPO DE RECURSO (solo referencia)
B49: CLASE | C49: QUÉ SIGNIFICA
B50: humano | C50: Admite operarios y método de emisión Manual; se usa en reprocesos.
B51: servicio | C51: Servicio de terceros: se compra con OC y se contrasta con la factura.
B52: (en blanco) | C52: Resto de recursos: máquinas, energía, activos fijos y extras.
B55: 6. CUENTAS MAYORES SUGERIDAS (solo referencia)
B56: CUENTA | C56: DESCRIPCIÓN
B57: 921101 | C57: Mano de obra directa de producción
B58: 921201 | C58: Servicios prestados por terceros
B59: 921301 | C59: Maquinaria y activos fijos de planta
B60: 921401 | C60: Energía y otros gastos de planta
B67: 7. PROVEEDORES (referencia · solo para recursos de tipo SERVICIO DE TERCEROS)
B68: CODIGO | C68: NOMBRE
B69: PROV-0005 | C69: LAVANDERIA LANDEO
B70: PROV-0006 | C70: LAVANDERIA ECOTEX
B71: PROV-0007 | C71: CESAR CURILLA
B72: PROV-0008 | C72: MISAEL ULIARTE
B73: PROV-0009 | C73: ORTENCIO CASTILLO
B74: PROV-0010 | C74: JUAN BLANQUILLO
...
